2021-07-09 12:33:31,042 ERROR: Exception on /user/susan [GET] [in d:\web projects\tblog\venv\lib\site-packages\flask\app.py:1454]
Traceback (most recent call last):
  File "d:\web projects\tblog\venv\lib\site-packages\flask\app.py", line 2070, in wsgi_app
    response = self.full_dispatch_request()
  File "d:\web projects\tblog\venv\lib\site-packages\flask\app.py", line 1515, in full_dispatch_request
    rv = self.handle_user_exception(e)
  File "d:\web projects\tblog\venv\lib\site-packages\flask\app.py", line 1513, in full_dispatch_request
    rv = self.dispatch_request()
  File "d:\web projects\tblog\venv\lib\site-packages\flask\app.py", line 1499, in dispatch_request
    return self.ensure_sync(self.view_functions[rule.endpoint])(**req.view_args)
  File "d:\web projects\tblog\venv\lib\site-packages\flask_login\utils.py", line 272, in decorated_view
    return func(*args, **kwargs)
  File "D:\web projects\Tblog\app\routes.py", line 100, in user
    return render_template("user.html", user=user, posts=posts.items, next_url=next_url, prev_url=prev_url)
  File "d:\web projects\tblog\venv\lib\site-packages\flask\templating.py", line 147, in render_template
    return _render(
  File "d:\web projects\tblog\venv\lib\site-packages\flask\templating.py", line 128, in _render
    rv = template.render(context)
  File "d:\web projects\tblog\venv\lib\site-packages\jinja2\environment.py", line 1304, in render
    self.environment.handle_exception()
  File "d:\web projects\tblog\venv\lib\site-packages\jinja2\environment.py", line 925, in handle_exception
    raise rewrite_traceback_stack(source=source)
  File "D:\web projects\Tblog\app\templates\user.html", line 1, in top-level template code
    {% extends "base.html" %}
  File "D:\web projects\Tblog\app\templates\base.html", line 1, in top-level template code
    {% extends 'bootstrap/base.html' %}
  File "d:\web projects\tblog\venv\lib\site-packages\flask_bootstrap\templates\bootstrap\base.html", line 1, in top-level template code
    {% block doc -%}
  File "d:\web projects\tblog\venv\lib\site-packages\flask_bootstrap\templates\bootstrap\base.html", line 4, in block 'doc'
    {%- block html %}
  File "d:\web projects\tblog\venv\lib\site-packages\flask_bootstrap\templates\bootstrap\base.html", line 20, in block 'html'
    {% block body -%}
  File "d:\web projects\tblog\venv\lib\site-packages\flask_bootstrap\templates\bootstrap\base.html", line 23, in block 'body'
    {% block content -%}
  File "D:\web projects\Tblog\app\templates\base.html", line 53, in block 'content'
    {% block app_content %}{% endblock %}
  File "D:\web projects\Tblog\app\templates\user.html", line 17, in block 'app_content'
    {{ form.hidden_tag() }}
  File "d:\web projects\tblog\venv\lib\site-packages\jinja2\environment.py", line 474, in getattr
    return getattr(obj, attribute)
jinja2.exceptions.UndefinedError: 'form' is undefined
2021-07-09 12:39:35,110 INFO: Tblog startup [in D:\web projects\Tblog\app\__init__.py:54]
2021-07-11 12:58:50,450 INFO: Tblog startup [in D:\web projects\Tblog\app\__init__.py:54]
2021-07-11 12:59:00,740 INFO: Tblog startup [in D:\web projects\Tblog\app\__init__.py:54]
2021-07-11 13:17:32,653 INFO: Tblog startup [in D:\web projects\Tblog\app\__init__.py:55]
2021-07-11 13:17:43,742 INFO: Tblog startup [in D:\web projects\Tblog\app\__init__.py:55]
2021-07-11 15:28:22,972 INFO: Tblog startup [in D:\web projects\Tblog\app\__init__.py:80]
2021-07-11 15:28:25,381 ERROR: Exception on / [GET] [in d:\web projects\tblog\venv\lib\site-packages\flask\app.py:1454]
Traceback (most recent call last):
  File "d:\web projects\tblog\venv\lib\site-packages\flask\app.py", line 2070, in wsgi_app
    response = self.full_dispatch_request()
  File "d:\web projects\tblog\venv\lib\site-packages\flask\app.py", line 1515, in full_dispatch_request
    rv = self.handle_user_exception(e)
  File "d:\web projects\tblog\venv\lib\site-packages\flask\app.py", line 1513, in full_dispatch_request
    rv = self.dispatch_request()
  File "d:\web projects\tblog\venv\lib\site-packages\flask\app.py", line 1499, in dispatch_request
    return self.ensure_sync(self.view_functions[rule.endpoint])(**req.view_args)
  File "d:\web projects\tblog\venv\lib\site-packages\flask_login\utils.py", line 271, in decorated_view
    return current_app.login_manager.unauthorized()
  File "d:\web projects\tblog\venv\lib\site-packages\flask_login\login_manager.py", line 174, in unauthorized
    redirect_url = make_login_url(login_view, next_url=request.url)
  File "d:\web projects\tblog\venv\lib\site-packages\flask_login\utils.py", line 120, in login_url
    base = expand_login_view(login_view)
  File "d:\web projects\tblog\venv\lib\site-packages\flask_login\utils.py", line 97, in expand_login_view
    return url_for(login_view)
  File "d:\web projects\tblog\venv\lib\site-packages\flask\helpers.py", line 338, in url_for
    return appctx.app.handle_url_build_error(error, endpoint, values)
  File "d:\web projects\tblog\venv\lib\site-packages\flask\helpers.py", line 325, in url_for
    rv = url_adapter.build(
  File "d:\web projects\tblog\venv\lib\site-packages\werkzeug\routing.py", line 2305, in build
    raise BuildError(endpoint, values, method, self)
werkzeug.routing.BuildError: Could not build url for endpoint 'login'. Did you mean 'auth.login' instead?
2021-07-11 15:38:57,428 INFO: Tblog startup [in D:\web projects\Tblog\app\__init__.py:80]
2021-07-11 15:38:59,168 ERROR: Exception on / [GET] [in d:\web projects\tblog\venv\lib\site-packages\flask\app.py:1454]
Traceback (most recent call last):
  File "d:\web projects\tblog\venv\lib\site-packages\flask\app.py", line 2070, in wsgi_app
    response = self.full_dispatch_request()
  File "d:\web projects\tblog\venv\lib\site-packages\flask\app.py", line 1515, in full_dispatch_request
    rv = self.handle_user_exception(e)
  File "d:\web projects\tblog\venv\lib\site-packages\flask\app.py", line 1513, in full_dispatch_request
    rv = self.dispatch_request()
  File "d:\web projects\tblog\venv\lib\site-packages\flask\app.py", line 1499, in dispatch_request
    return self.ensure_sync(self.view_functions[rule.endpoint])(**req.view_args)
  File "d:\web projects\tblog\venv\lib\site-packages\flask_login\utils.py", line 271, in decorated_view
    return current_app.login_manager.unauthorized()
  File "d:\web projects\tblog\venv\lib\site-packages\flask_login\login_manager.py", line 174, in unauthorized
    redirect_url = make_login_url(login_view, next_url=request.url)
  File "d:\web projects\tblog\venv\lib\site-packages\flask_login\utils.py", line 120, in login_url
    base = expand_login_view(login_view)
  File "d:\web projects\tblog\venv\lib\site-packages\flask_login\utils.py", line 97, in expand_login_view
    return url_for(login_view)
  File "d:\web projects\tblog\venv\lib\site-packages\flask\helpers.py", line 338, in url_for
    return appctx.app.handle_url_build_error(error, endpoint, values)
  File "d:\web projects\tblog\venv\lib\site-packages\flask\helpers.py", line 325, in url_for
    rv = url_adapter.build(
  File "d:\web projects\tblog\venv\lib\site-packages\werkzeug\routing.py", line 2305, in build
    raise BuildError(endpoint, values, method, self)
werkzeug.routing.BuildError: Could not build url for endpoint 'login'. Did you mean 'auth.login' instead?
2021-07-11 15:40:03,138 INFO: Tblog startup [in D:\web projects\Tblog\app\__init__.py:80]
2021-07-11 15:40:06,600 ERROR: Exception on / [GET] [in d:\web projects\tblog\venv\lib\site-packages\flask\app.py:1454]
Traceback (most recent call last):
  File "d:\web projects\tblog\venv\lib\site-packages\flask\app.py", line 2070, in wsgi_app
    response = self.full_dispatch_request()
  File "d:\web projects\tblog\venv\lib\site-packages\flask\app.py", line 1515, in full_dispatch_request
    rv = self.handle_user_exception(e)
  File "d:\web projects\tblog\venv\lib\site-packages\flask\app.py", line 1513, in full_dispatch_request
    rv = self.dispatch_request()
  File "d:\web projects\tblog\venv\lib\site-packages\flask\app.py", line 1499, in dispatch_request
    return self.ensure_sync(self.view_functions[rule.endpoint])(**req.view_args)
  File "d:\web projects\tblog\venv\lib\site-packages\flask_login\utils.py", line 271, in decorated_view
    return current_app.login_manager.unauthorized()
  File "d:\web projects\tblog\venv\lib\site-packages\flask_login\login_manager.py", line 174, in unauthorized
    redirect_url = make_login_url(login_view, next_url=request.url)
  File "d:\web projects\tblog\venv\lib\site-packages\flask_login\utils.py", line 120, in login_url
    base = expand_login_view(login_view)
  File "d:\web projects\tblog\venv\lib\site-packages\flask_login\utils.py", line 97, in expand_login_view
    return url_for(login_view)
  File "d:\web projects\tblog\venv\lib\site-packages\flask\helpers.py", line 338, in url_for
    return appctx.app.handle_url_build_error(error, endpoint, values)
  File "d:\web projects\tblog\venv\lib\site-packages\flask\helpers.py", line 325, in url_for
    rv = url_adapter.build(
  File "d:\web projects\tblog\venv\lib\site-packages\werkzeug\routing.py", line 2305, in build
    raise BuildError(endpoint, values, method, self)
werkzeug.routing.BuildError: Could not build url for endpoint 'login'. Did you mean 'auth.login' instead?
2021-07-16 13:51:28,807 INFO: Tblog startup [in D:\web projects\Tblog\app\__init__.py:91]
2021-07-16 13:51:28,807 INFO: Tblog startup [in D:\web projects\Tblog\app\__init__.py:91]
2021-07-16 13:51:55,141 INFO: Tblog startup [in D:\web projects\Tblog\app\__init__.py:91]
2021-07-16 13:51:55,141 INFO: Tblog startup [in D:\web projects\Tblog\app\__init__.py:91]
2021-07-16 21:17:15,273 INFO: Tblog startup [in D:\web projects\Tblog\app\__init__.py:91]
2021-07-16 21:17:15,273 INFO: Tblog startup [in D:\web projects\Tblog\app\__init__.py:91]
2021-07-16 21:17:26,583 INFO: Tblog startup [in D:\web projects\Tblog\app\__init__.py:91]
2021-07-16 21:17:26,583 INFO: Tblog startup [in D:\web projects\Tblog\app\__init__.py:91]
